{"error": "Traceback (most recent call last):\n  File \"/Users/ninosandlarz/Desktop/Enjmin/FourmisTP/tools_mac/sandbox.py\", line 378, in start\n    self.command_process = subprocess.Popen(shell_command,\n  File \"/Applications/Xcode.app/Contents/Developer/Library/Frameworks/Python3.framework/Versions/3.9/lib/python3.9/subprocess.py\", line 951, in __init__\n    self._execute_child(args, executable, preexec_fn, close_fds,\n  File \"/Applications/Xcode.app/Contents/Developer/Library/Frameworks/Python3.framework/Versions/3.9/lib/python3.9/subprocess.py\", line 1821, in _execute_child\n    raise child_exception_type(errno_num, err_msg, err_filename)\nFileNotFoundError: [Errno 2] No such file or directory: './../cpp_starter_package/MyBot'\n\nDuring handling of the above exception, another exception occurred:\n\nTraceback (most recent call last):\n  File \"/Users/ninosandlarz/Desktop/Enjmin/FourmisTP/tools_mac/engine.py\", line 93, in run_game\n    sandbox.start(bot_cmd)\n  File \"/Users/ninosandlarz/Desktop/Enjmin/FourmisTP/tools_mac/sandbox.py\", line 385, in start\n    raise SandboxError('Failed to start {0}'.format(shell_command))\nsandbox.SandboxError: Failed to start ['./../cpp_starter_package/MyBot']\n", "playernames": [null, "HunterBot.py", "HunterBot.py", "GreedyBot.py"]}